Workbook

Sheet Database
A1: # | B1: 公司名 | C1: 区域 | D1: 指标名称（原始） | E1: 报告周期 | F1: 数据值 | G1: 单位 | H1: 数据来源 | I1: 所在页码 | J1: 原文摘录 | K1: 归一化周期 | L1: 归一化指标名称 | M1: 归一化指标数值 | N1: 归一化计算逻辑/折算说明 | O1: 备注（披露范围等） | P1: 最后更新 | Q1: 人工核验
A2: 18 | B2: 安踏 | C2: 中国公司 | D2: 收入 | E2: FY2025 | F2: 80219000000 | G2: RMB | H2: 安踏体育：二零二五年年报.pdf | I2: 13 | J2: 收入 80219 | K2: 2025 | L2: 营业收入 | M2: 80219000 | N2: 百万元×1000=千元RMB | O2: 集团层面TOTAL | P2: 2026-06-02
A3: 18 | B3: 安踏 | C3: 中国公司 | D3: 毛利 | E3: FY2025 | F3: 49734000000 | G3: RMB | H3: 安踏体育：二零二五年年报.pdf | I3: 13 | J3: 毛利 49734 | K3: 2025 | L3: 毛利 | M3: 49734000 | N3: 百万元×1000=千元RMB | O3: 集团层面TOTAL | P3: 2026-06-02
A4: 18 | B4: 安踏 | C4: 中国公司 | D4: 毛利率 | E4: FY2025 | F4: 62 | G4: % | H4: 安踏体育：二零二五年年报.pdf | I4: 13 | J4: 毛利率 62.0% | K4: 2025 | L4: 毛利率 | M4: 62 | N4: 直接使用原始百分比 | O4: 集团层面TOTAL | P4: 2026-06-02
A5: 18 | B5: 安踏 | C5: 中国公司 | D5: 经营溢利 | E5: FY2025 | F5: 19091000000 | G5: RMB | H5: 安踏体育：二零二五年年报.pdf | I5: 13 | J5: 经营溢利 19091 | K5: 2025 | L5: 经营利润 | M5: 19091000 | N5: 百万元×1000=千元RMB | O5: 集团层面TOTAL | P5: 2026-06-02
A6: 18 | B6: 安踏 | C6: 中国公司 | D6: 净利率 | E6: FY2025 | F6: 19.5 | G6: % | H6: 安踏体育：二零二五年年报.pdf | I6: 13 | J6: 净利率 19.5% | K6: 2025 | L6: 净利率 | M6: 19.5 | N6: 净利率=净利润÷收入×100% | O6: 集团层面TOTAL | P6: 2026-06-02
A7: 18 | B7: 安踏 | C7: 中国公司 | D7: 收入 | E7: FY2024 | F7: 70826000000 | G7: RMB | H7: 安踏体育：二零二五年年报.pdf | I7: 13 | J7: 收入 70826 | K7: 2024 | L7: 营业收入 | M7: 70826000 | N7: 百万元×1000=千元RMB | O7: 集团层面TOTAL | P7: 2026-06-02
A8: 18 | B8: 安踏 | C8: 中国公司 | D8: 毛利 | E8: FY2024 | F8: 44032000000 | G8: RMB | H8: 安踏体育：二零二五年年报.pdf | I8: 13 | J8: 毛利 44032 | K8: 2024 | L8: 毛利 | M8: 44032000 | N8: 百万元×1000=千元RMB | O8: 集团层面TOTAL | P8: 2026-06-02
A9: 18 | B9: 安踏 | C9: 中国公司 | D9: 毛利率 | E9: FY2024 | F9: 62.2 | G9: % | H9: 安踏体育：二零二五年年报.pdf | I9: 13 | J9: 毛利率 62.2% | K9: 2024 | L9: 毛利率 | M9: 62.2 | N9: 直接使用原始百分比 | O9: 集团层面TOTAL | P9: 2026-06-02
A10: 18 | B10: 安踏 | C10: 中国公司 | D10: 经营溢利 | E10: FY2024 | F10: 16595000000 | G10: RMB | H10: 安踏体育：二零二五年年报.pdf | I10: 13 | J10: 经营溢利 16595 | K10: 2024 | L10: 经营利润 | M10: 16595000 | N10: 百万元×1000=千元RMB | O10: 集团层面TOTAL | P10: 2026-06-02
A11: 18 | B11: 安踏 | C11: 中国公司 | D11: 净利率 | E11: FY2024 | F11: 24 | G11: % | H11: 安踏体育：二零二五年年报.pdf | I11: 13 | J11: 净利率 24.0% | K11: 2024 | L11: 净利率 | M11: 24 | N11: 净利率=净利润÷收入×100% | O11: 集团层面TOTAL | P11: 2026-06-02
A12: 18 | B12: 安踏 | C12: 中国公司 | D12: 收入 | E12: FY2023 | F12: 62356000000 | G12: RMB | H12: 安踏体育：二零二五年年报.pdf | I12: 13 | J12: 收入 62356 | K12: 2023 | L12: 营业收入 | M12: 62356000 | N12: 百万元×1000=千元RMB | O12: 集团层面TOTAL | P12: 2026-06-02
A13: 18 | B13: 安踏 | C13: 中国公司 | D13: 毛利 | E13: FY2023 | F13: 39028000000 | G13: RMB | H13: 安踏体育：二零二五年年报.pdf | I13: 13 | J13: 毛利 39028 | K13: 2023 | L13: 毛利 | M13: 39028000 | N13: 百万元×1000=千元RMB | O13: 集团层面TOTAL | P13: 2026-06-02
... A67: 4 | B67: Adidas | C67: 大中华区 | D67: Operating margin | E67: FY2023 | F67: 17.3 | G67: % | H67: adidas_annual_report_2024_EN_Final_secured.pdf | I67: 113 | J67: Operating margin 17.3% | K67: 2023 | L67: 经营利润率 | M67: 17.3 | N67: 直接使用原始百分比 | O67: 大中华区 | P67: 2026-06-02
A68: 2 | B68: 斯凯奇 | C68: TOTAL | D68: Net sales | E68: FY2024 | F68: 8969351 | G68: 千美元 | H68: annual-report-10-k-73611-2025-02-28-09-59-17.pdf | I68: 24 | J68: Net sales $8,969,351.0 million (千美元) | K68: 2024 | L68: 营业收入 | M68: 64579327200 | N68: 千美元×7.2=千元人民币 | O68: 集团TOTAL | P68: 2026-06-02 | Q68: revised
A69: 2 | B69: 斯凯奇 | C69: TOTAL | D69: Gross profit | E69: FY2024 | F69: 4767439 | G69: 千美元 | H69: annual-report-10-k-73611-2025-02-28-09-59-17.pdf | I69: 24 | J69: Net sales $4,767,439.0 million (千美元) | K69: 2024 | L69: 毛利 | M69: 34325560800 | N69: 千美元×7.2=千元人民币 | O69: 集团TOTAL | P69: 2026-06-02 | Q69: revised
A70: 2 | B70: 斯凯奇 | C70: TOTAL | D70: Gross margin | E70: FY2024 | F70: 53.2 | G70: % | H70: annual-report-10-k-73611-2025-02-28-09-59-17.pdf | I70: 24 | J70: Gross margin 53.2% | K70: 2024 | L70: 毛利率 | M70: 53.2 | N70: 直接使用 | O70: 集团TOTAL | P70: 2026-06-02 | Q70: ok
A71: 2 | B71: 斯凯奇 | C71: TOTAL | D71: Net sales | E71: FY2023 | F71: 8000342 | G71: 千美元 | H71: annual-report-10-k-73611-2025-02-28-09-59-17.pdf | I71: 24 | J71: Net sales $8,000,342.0 million (千美元) | K71: 2023 | L71: 营业收入 | M71: 57602462400 | N71: 千美元×7.2=千元人民币 | O71: 集团TOTAL | P71: 2026-06-02 | Q71: revised
A72: 2 | B72: 斯凯奇 | C72: TOTAL | D72: Gross profit | E72: FY2023 | F72: 4152404 | G72: 千美元 | H72: annual-report-10-k-73611-2025-02-28-09-59-17.pdf | I72: 24 | J72: Net sales $4,152,404.0 million (千美元) | K72: 2023 | L72: 毛利 | M72: 29897308800 | N72: 千美元×7.2=千元人民币 | O72: 集团TOTAL | P72: 2026-06-02 | Q72: revised
A73: 2 | B73: 斯凯奇 | C73: TOTAL | D73: Gross margin | E73: FY2023 | F73: 51.9 | G73: % | H73: annual-report-10-k-73611-2025-02-28-09-59-17.pdf | I73: 24 | J73: Gross margin 51.9% | K73: 2023 | L73: 毛利率 | M73: 51.9 | N73: 直接使用 | O73: 集团TOTAL | P73: 2026-06-02 | Q73: ok
A74: 2 | B74: 斯凯奇 | C74: TOTAL | D74: Operating income | E74: FY2024 | F74: 904257 | G74: 千美元 | H74: annual-report-10-k-73611-2025-02-28-09-59-17.pdf | I74: 24 | J74: Net sales $904.3 million (千美元) | K74: 2024 | L74: 经营利润 | M74: 6510650.4 | N74: 千美元×7.2=千元人民币 | O74: 集团TOTAL | P74: 2026-06-02 | Q74: ok
A75: 2 | B75: 斯凯奇 | C75: TOTAL | D75: Net income | E75: FY2024 | F75: 729613 | G75: 千美元 | H75: annual-report-10-k-73611-2025-02-28-09-59-17.pdf | I75: 24 | J75: Net sales $729.6 million (千美元) | K75: 2024 | L75: 净利润 | M75: 5253213.6 | N75: 千美元×7.2=千元人民币 | O75: 集团TOTAL | P75: 2026-06-02 | Q75: ok
A76: 2 | B76: 斯凯奇 | C76: TOTAL | D76: Operating margin | E76: FY2024 | F76: 10.1 | G76: % | H76: annual-report-10-k-73611-2025-02-28-09-59-17.pdf | I76: 24 | J76: Operating margin 10.1% | K76: 2024 | L76: 经营利润率 | M76: 10.1 | N76: 直接使用 | O76: 集团TOTAL | P76: 2026-06-02 | Q76: ok
A77: 2 | B77: 斯凯奇 | C77: TOTAL | D77: Net margin | E77: FY2024 | F77: 8.1 | G77: % | H77: annual-report-10-k-73611-2025-02-28-09-59-17.pdf | I77: 24 | J77: Net margin 8.1% | K77: 2024 | L77: 净利率 | M77: 8.1 | N77: 直接使用 | O77: 集团TOTAL | P77: 2026-06-02 | Q77: ok
A78: 2 | B78: 斯凯奇 | C78: TOTAL | D78: Operating income | E78: FY2023 | F78: 784786 | G78: 千美元 | H78: annual-report-10-k-73611-2025-02-28-09-59-17.pdf | I78: 24 | J78: Net sales $784.8 million (千美元) | K78: 2023 | L78: 经营利润 | M78: 5650459.2 | N78: 千美元×7.2=千元人民币 | O78: 集团TOTAL | P78: 2026-06-02 | Q78: ok
A79: 2 | B79: 斯凯奇 | C79: TOTAL | D79: Net income | E79: FY2023 | F79: 545799 | G79: 千美元 | H79: annual-report-10-k-73611-2025-02-28-09-59-17.pdf | I79: 24 | J79: Net sales $545.8 million (千美元) | K79: 2023 | L79: 净利润 | M79: 3929752.8 | N79: 千美元×7.2=千元人民币 | O79: 集团TOTAL | P79: 2026-06-02 | Q79: ok
... A81: 2 | B81: 斯凯奇 | C81: TOTAL | D81: Net margin | E81: FY2023 | F81: 6.8 | G81: % | H81: annual-report-10-k-73611-2025-02-28-09-59-17.pdf | I81: 24 | J81: Net margin 6.8% | K81: 2023 | L81: 净利率 | M81: 6.8 | N81: 直接使用 | O81: 集团TOTAL | P81: 2026-06-02 | Q81: ok
A82: 15 | B82: 安德玛 | C82: TOTAL | D82: Net revenues | E82: FY2025 | F82: 5164310 | G82: 千美元 | H82: UA_2025_AnnualReport.pdf | I82: 35 | J82: Net revenues $5164310K | K82: 2025 | L82: 营业收入 | M82: 37183032 | N82: 千美元×7.2=千元人民币 | O82: 集团TOTAL | P82: 2026-06-02
A83: 15 | B83: 安德玛 | C83: TOTAL | D83: Gross profit | E83: FY2025 | F83: 2474744 | G83: 千美元 | H83: UA_2025_AnnualReport.pdf | I83: 35 | J83: Gross profit $2474744K | K83: 2025 | L83: 毛利 | M83: 17818157 | N83: 千美元×7.2=千元人民币 | O83: 集团TOTAL | P83: 2026-06-02
A84: 15 | B84: 安德玛 | C84: TOTAL | D84: Gross margin | E84: FY2025 | F84: 47.9 | G84: % | H84: UA_2025_AnnualReport.pdf | I84: 35 | J84: Gross margin 47.9% | K84: 2025 | L84: 毛利率 | M84: 47.9 | N84: 直接使用 | O84: 集团TOTAL | P84: 2026-06-02
A85: 15 | B85: 安德玛 | C85: TOTAL | D85: Income from operations | E85: FY2025 | F85: -185216 | G85: 千美元 | H85: UA_2025_AnnualReport.pdf | I85: 35 | J85: Operating income $-185216K | K85: 2025 | L85: 经营利润 | M85: -1333555.2 | N85: 千美元×7.2=千元人民币 | O85: 集团TOTAL | P85: 2026-06-02
A86: 15 | B86: 安德玛 | C86: TOTAL | D86: Operating margin | E86: FY2025 | F86: -3.6 | G86: % | H86: UA_2025_AnnualReport.pdf | I86: 35 | J86: Operating margin -3.6% | K86: 2025 | L86: 经营利润率 | M86: -3.6 | N86: 直接使用 | O86: 集团TOTAL | P86: 2026-06-02
A87: 15 | B87: 安德玛 | C87: TOTAL | D87: Net income | E87: FY2025 | F87: -201267 | G87: 千美元 | H87: UA_2025_AnnualReport.pdf | I87: 35 | J87: Net income $-201267K | K87: 2025 | L87: 净利润 | M87: -1449122.4 | N87: 千美元×7.2=千元人民币 | O87: 集团TOTAL | P87: 2026-06-02
A88: 15 | B88: 安德玛 | C88: TOTAL | D88: Net margin | E88: FY2025 | F88: -3.9 | G88: % | H88: UA_2025_AnnualReport.pdf | I88: 35 | J88: Net margin -3.9% | K88: 2025 | L88: 净利率 | M88: -3.9 | N88: 直接使用 | O88: 集团TOTAL | P88: 2026-06-02
A89: 15 | B89: 安德玛 | C89: TOTAL | D89: Net revenues | E89: FY2024 | F89: 5701879 | G89: 千美元 | H89: UA_2025_AnnualReport.pdf | I89: 35 | J89: Net revenues $5701879K | K89: 2024 | L89: 营业收入 | M89: 41053529 | N89: 千美元×7.2=千元人民币 | O89: 集团TOTAL | P89: 2026-06-02
A90: 15 | B90: 安德玛 | C90: TOTAL | D90: Gross profit | E90: FY2024 | F90: 2630253 | G90: 千美元 | H90: UA_2025_AnnualReport.pdf | I90: 35 | J90: Gross profit $2630253K | K90: 2024 | L90: 毛利 | M90: 18937822 | N90: 千美元×7.2=千元人民币 | O90: 集团TOTAL | P90: 2026-06-02
A91: 15 | B91: 安德玛 | C91: TOTAL | D91: Gross margin | E91: FY2024 | F91: 46.1 | G91: % | H91: UA_2025_AnnualReport.pdf | I91: 35 | J91: Gross margin 46.1% | K91: 2024 | L91: 毛利率 | M91: 46.1 | N91: 直接使用 | O91: 集团TOTAL | P91: 2026-06-02
A92: 15 | B92: 安德玛 | C92: TOTAL | D92: Income from operations | E92: FY2024 | F92: 229751 | G92: 千美元 | H92: UA_2025_AnnualReport.pdf | I92: 35 | J92: Operating income $229751K | K92: 2024 | L92: 经营利润 | M92: 1654207.2 | N92: 千美元×7.2=千元人民币 | O92: 集团TOTAL | P92: 2026-06-02
A93: 15 | B93: 安德玛 | C93: TOTAL | D93: Operating margin | E93: FY2024 | F93: 4 | G93: % | H93: UA_2025_AnnualReport.pdf | I93: 35 | J93: Operating margin 4.0% | K93: 2024 | L93: 经营利润率 | M93: 4 | N93: 直接使用 | O93: 集团TOTAL | P93: 2026-06-02
... A101: 15 | B101: 安德玛 | C101: TOTAL | D101: Net margin | E101: FY2023 | F101: 3.8 | G101: % | H101: UA_2025_AnnualReport.pdf | I101: 35 | J101: Net margin 3.8% | K101: 2023 | L101: 净利率 | M101: 3.8 | N101: 直接使用 | O101: 集团TOTAL | P101: 2026-06-02
...

Sheet 数透
A2: 归一化指标名称 | B2: 营业收入 | J2: 归一化指标名称 | K2: 毛利率 | P2: 归一化指标名称 | Q2: 净利率 | V2: 归一化指标名称 | W2: 经营费用率 | AB2: 区域 | AC2: (Multiple Items)
A3: 区域 | B3: (Multiple Items) | J3: 区域 | K3: (Multiple Items) | P3: 区域 | Q3: (Multiple Items) | V3: 区域 | W3: (Multiple Items) | AB3: 公司名 | AC3: 安踏
A5: 平均值项:归一化指标数值 | B5: Column Labels | J5: 平均值项:归一化指标数值 | K5: Column Labels | P5: 平均值项:归一化指标数值 | Q5: Column Labels | V5: 平均值项:归一化指标数值 | W5: Column Labels | AB5: 求和项:归一化指标数值 | AC5: Column Labels
A6: Row Labels | B6: 2023 | C6: 2024 | D6: 2025 | E6: Grand Total | F6: FY23-24变化率(%) | G6: FY24-25变化率(%) | H6: 覆盖区域 | J6: Row Labels | K6: 2023 | L6: 2024 | M6: 2025 | N6: Grand Total | P6: Row Labels | Q6: 2023 | R6: 2024 | S6: 2025 | T6: Grand Total | V6: Row Labels | W6: 2023 | X6: 2024 | Y6: 2025 | Z6: Grand Total | AB6: Row Labels | AC6: 2023 | AD6: 2024 | AE6: 2025 | AF6: Grand Total
A7: 安踏 | B7: 62356000 | C7: 70826000 | D7: 80219000 | E7: 71133667 | F7: =C7/B7-1 -> 0.13583296 | G7: =D7/C7-1 -> 0.13262079 | H7: =VLOOKUP(A7,'brand list'!$G$1:$H$29,2,0) -> 中国公司 | J7: 361度 | K7: 41.1 | L7: 41.5 | M7: 41.5 | N7: 41.366667 | P7: 361度 | Q7: 11.4 | R7: 11.4 | S7: 11.7 | T7: 11.5 | V7: 361度 | W7: 25.6 | X7: 24.7 | Y7: 22.3 | Z7: 24.2 | AB7: 广告费用率 | AC7: 10 | AD7: 10.2 | AE7: 10.5 | AF7: 30.7
A8: Nike | B8: 52185600 | C8: 54324000 | D8: 47419200 | E8: 51309600 | F8: =C8/B8-1 -> 0.040976821 | G8: =D8/C8-1 -> -0.12710404 | H8: =VLOOKUP(A8,'brand list'!$G$1:$H$29,2,0) -> 大中华区 | J8: Adidas | K8: 48.7 | L8: 49.6 | M8: 52.6 | N8: 50.3 | P8: Nike | Q8: 23.6 | R8: 23 | S8: 18.2 | T8: 21.6 | V8: Adidas | W8: 45 | X8: 43 | Y8: 42 | Z8: 43.333333 | AB8: 员工费用率 | AC8: 10.8 | AD8: 11 | AE8: 11.5 | AF8: 33.3
A9: Inditex | B9: 37408800 | C9: 37065600 | D9: 36114000 | E9: 36913500 | F9: =C9/B9-1 -> -0.0091743119 | G9: =D9/C9-1 -> -0.025673401 | H9: =VLOOKUP(A9,'brand list'!$G$1:$H$29,2,0) -> 亚太/其他地区 | J9: Nike | K9: 51 | L9: 50.2 | M9: 46 | N9: 49.066667 | P9: 安踏 | Q9: 16.42 | R9: 24 | S9: 19.5 | T9: 19.973333 | V9: Nike | W9: 33.8 | X9: 34.5 | Y9: 35.7 | Z9: 34.666667 | AB9: 研发费用率 | AC9: 2.6 | AD9: 2.8 | AE9: 2.7 | AF9: 8.1
A10: Uniqlo | B10: 29769600 | C10: 32496000 | D10: 31209600 | E10: 31158400 | F10: =C10/B10-1 -> 0.09158336 | G10: =D10/C10-1 -> -0.039586411 | H10: =VLOOKUP(A10,'brand list'!$G$1:$H$29,2,0) -> 大中华区 | J10: 安踏 | K10: 62.6 | L10: 62.2 | M10: 62 | N10: 62.266667 | P10: 比音勒芬 | Q10: 25.75 | R10: 19.5 | S10: 12.77 | T10: 19.34 | V10: 安踏 | W10: 23.4 | X10: 24 | Y10: 24.7 | Z10: 24.033333 | AB10: Grand Total | AC10: 23.4 | AD10: 24 | AE10: 24.7 | AF10: 72.1
A11: 李宁 | B11: 27598000 | C11: 28676000 | D11: 29598000 | E11: 28624000 | F11: =C11/B11-1 -> 0.039060802 | G11: =D11/C11-1 -> 0.032152322 | H11: =VLOOKUP(A11,'brand list'!$G$1:$H$29,2,0) -> 中国公司 | J11: 比音勒芬 | K11: 77.5 | L11: 76.29 | M11: 75.35 | N11: 76.38 | P11: 李宁 | Q11: 8.6 | R11: 8.8 | S11: 9.9 | T11: 9.1 | V11: 比音勒芬 | W11: 34 | X11: 34.5 | Y11: 35 | Z11: 34.5
A12: 滔搏 | B12: 27073200 | C12: 28933200 | D12: 27012900 | E12: 27673100 | F12: =C12/B12-1 -> 0.068702628 | G12: =D12/C12-1 -> -0.066370122 | H12: =VLOOKUP(A12,'brand list'!$G$1:$H$29,2,0) -> 中国公司 | J12: 李宁 | K12: 48.4 | L12: 49.4 | M12: 49 | N12: 48.933333 | P12: 探路者 | Q12: 5.16 | R12: 6.7 | S12: 5.72 | T12: 5.86 | V12: 李宁 | W12: 37 | X12: 37.5 | Y12: 38 | Z12: 37.5
A13: Adidas | B13: 24882000 | C13: 26980200 | D13: 28259400 | E13: 26707200 | F13: =C13/B13-1 -> 0.084326019 | G13: =D13/C13-1 -> 0.047412547 | H13: =VLOOKUP(A13,'brand list'!$G$1:$H$29,2,0) -> 大中华区 | J13: 牧高笛 | L13: 28.57 | M13: 26.62 | N13: 27.595 | P13: 滔搏 | Q13: 6.8 | R13: 7.6 | S13: 4.8 | T13: 6.4 | V13: 牧高笛 | W13: 24 | X13: 24.5 | Y13: 25 | Z13: 24.5
A14: 特步 | B14: 12742900 | C14: 13577200 | D14: 14151100 | E14: 13490400 | F14: =C14/B14-1 -> 0.065471753 | G14: =D14/C14-1 -> 0.042269393 | H14: =VLOOKUP(A14,'brand list'!$G$1:$H$29,2,0) -> 中国公司 | J14: 探路者 | K14: 44.1 | L14: 44.67 | M14: 47.57 | N14: 45.446667 | P14: 特步 | Q14: 8.1 | R14: 9.1 | S14: 9.7 | T14: 8.9666667 | V14: 探路者 | W14: 29 | X14: 29.5 | Y14: 30 | Z14: 29.5
A15: 威富集团 | B15: 10103501 | C15: 10243476 | D15: 10102990 | E15: 10149989 | F15: =C15/B15-1 -> 0.013854129 | G15: =D15/C15-1 -> -0.013714719 | H15: =VLOOKUP(A15,'brand list'!$G$1:$H$29,2,0) -> 亚太区 | J15: 滔搏 | K15: 41.7 | L15: 41.8 | M15: 38.4 | N15: 40.633333 | P15: Grand Total | Q15: 13.22875 | R15: 13.7625 | S15: 11.53625 | T15: 12.8425 | V15: 滔搏 | W15: 33.8 | X15: 32.8 | Y15: 33.1 | Z15: 33.233333
A16: 361度 | B16: 8423257 | C16: 10073510 | D16: 11145829 | E16: 9880865.3 | F16: =C16/B16-1 -> 0.19591626 | G16: =D16/C16-1 -> 0.10644939 | H16: =VLOOKUP(A16,'brand list'!$G$1:$H$29,2,0) -> 中国公司 | J16: 特步 | K16: 41.8 | L16: 43.2 | M16: 42.8 | N16: 42.6 | V16: Grand Total | W16: 31.733333 | X16: 31.666667 | Y16: 31.755556 | Z16: 31.718519
A17: Lululemon | B17: 6939072 | C17: 9801626.4 | D17: 12634553 | E17: 9791750.4 | F17: =C17/B17-1 -> 0.41252698 | G17: =D17/C17-1 -> 0.28902616 | H17: =VLOOKUP(A17,'brand list'!$G$1:$H$29,2,0) -> 中国内地 | J17: Grand Total | K17: 50.766667 | L17: 48.743 | M17: 48.184 | N17: 49.178276
A18: 亚玛芬 | B18: 6082560 | C18: 9346320 | D18: 13405680 | E18: 9611520 | F18: =C18/B18-1 -> 0.5365767 | G18: =D18/C18-1 -> 0.43432709 | H18: =VLOOKUP(A18,'brand list'!$G$1:$H$29,2,0) -> 大中华区
A19: 斯凯奇 | B19: 8846136 | C19: 8770939.2 | E19: 8808537.6 | F19: =C19/B19-1 -> -0.008500525 | H19: =VLOOKUP(A19,'brand list'!$G$1:$H$29,2,0) -> 中国内地
A20: 捷安特 | B20: 6624465.1 | C20: 7118540.9 | D20: 4478649.5 | E20: 6073885.2 | F20: =C20/B20-1 -> 0.074583514 | G20: =D20/C20-1 -> -0.37084727 | H20: =VLOOKUP(A20,'brand list'!$G$1:$H$29,2,0) -> 亚太区 | J20: 归一化指标名称 | K20: 毛利率 | P20: 归一化指标名称 | Q20: 净利率 | V20: 归一化指标名称 | W20: 经营费用率
A21: 安德玛 | B21: 5942433.6 | C21: 6285736.8 | D21: 5439146.4 | E21: 5889105.6 | F21: =C21/B21-1 -> 0.057771483 | G21: =D21/C21-1 -> -0.13468435 | H21: =VLOOKUP(A21,'brand list'!$G$1:$H$29,2,0) -> 亚太区 | J21: 区域 | K21: TOTAL | P21: 区域 | Q21: TOTAL | V21: 区域 | W21: TOTAL
A22: 彪马 | B22: 4541160 | C22: 4711200 | D22: 3809520 | E22: 4353960 | F22: =C22/B22-1 -> 0.037444177 | G22: =D22/C22-1 -> -0.19139073 | H22: =VLOOKUP(A22,'brand list'!$G$1:$H$29,2,0) -> 大中华区
A23: 哥伦比亚 | B23: 3744000 | C23: 4037083.2 | D23: 4400272.8 | E23: 4060452 | F23: =C23/B23-1 -> 0.078280769 | G23: =D23/C23-1 -> 0.089963368 | H23: =VLOOKUP(A23,'brand list'!$G$1:$H$29,2,0) -> 亚太区 | J23: 平均值项:归一化指标数值 | K23: Column Labels | P23: 平均值项:归一化指标数值 | Q23: Column Labels | V23: 平均值项:归一化指标数值 | W23: Column Labels
A24: 比音勒芬 | B24: 3536132.7 | C24: 4004463.3 | D24: 4313911 | E24: 3951502.3 | F24: =C24/B24-1 -> 0.13244147 | G24: =D24/C24-1 -> 0.077275682 | H24: =VLOOKUP(A24,'brand list'!$G$1:$H$29,2,0) -> 中国公司 | J24: Row Labels | K24: 2023 | L24: 2024 | M24: 2025 | N24: Grand Total | P24: Row Labels | Q24: 2023 | R24: 2024 | S24: 2025 | T24: Grand Total | V24: Row Labels | W24: 2023 | X24: 2024 | Y24: 2025 | Z24: Grand Total
A25: ASICS | B25: 3053952 | C25: 3985248 | D25: 4759248 | E25: 3932816 | F25: =C25/B25-1 -> 0.30494782 | G25: =D25/C25-1 -> 0.19421627 | H25: =VLOOKUP(A25,'brand list'!$G$1:$H$29,2,0) -> 中国内地 | J25: ASICS | K25: 52 | L25: 55.83 | M25: 56.8 | N25: 54.876667 | P25: ASICS | Q25: 6.2 | R25: 10.805581 | T25: 9.2703876 | V25: ASICS | W25: 36.2 | X25: 41.08 | Y25: 39.23 | Z25: 38.836667
A26: Topgolf Callaway | B26: 3829680 | C26: 3510720 | D26: 2614320 | E26: 3318240 | F26: =C26/B26-1 -> -0.083286332 | G26: =D26/C26-1 -> -0.25533224 | H26: =VLOOKUP(A26,'brand list'!$G$1:$H$29,2,0) -> 亚太区 | J26: Inditex | K26: 57.757254 | L26: 57.835473 | M26: 58.25306 | N26: 57.948596 | P26: Inditex | Q26: 15.212777 | R26: 15.212777 | S26: 15.60305 | T26: 15.342868 | V26: Lululemon | W26: 35.3 | X26: 35.5 | Y26: 36.6 | Z26: 35.8
A27: Canada Goose | B27: 2322100 | C27: 2345750 | D27: 2740650 | E27: 2469500 | F27: =C27/B27-1 -> 0.010184747 | G27: =D27/C27-1 -> 0.16834701 | H27: =VLOOKUP(A27,'brand list'!$G$1:$H$29,2,0) -> 大中华区 | J27: Lululemon | K27: 58.3 | L27: 59.2 | M27: 56.6 | N27: 58.033333 | P27: Lululemon | Q27: 16.1 | R27: 17.1 | S27: 14.2 | T27: 15.8 | V27: 安德玛 | W27: 40.8 | X27: 41.5 | Y27: 42 | Z27: 41.433333
A28: 昂跑 | B28: 1142910 | C28: 2107620 | D28: 4139910 | E28: 2463480 | F28: =C28/B28-1 -> 0.84408221 | G28: =D28/C28-1 -> 0.96425826 | H28: =VLOOKUP(A28,'brand list'!$G$1:$H$29,2,0) -> 亚太区 | J28: 安德玛 | K28: 45.5 | L28: 46.1 | M28: 47.9 | N28: 46.5 | P28: 安德玛 | Q28: 3.8 | R28: 4.1 | S28: -3.9 | T28: 1.3333333 | V28: 昂跑 | W28: 49.5 | X28: 51.5 | Y28: 50.3 | Z28: 50.433333
A29: 奔赴自然(伯希和） | B29: 908100 | C29: 1766100 | D29: 2793000 | E29: 1822400 | F29: =C29/B29-1 -> 0.94482986 | G29: =D29/C29-1 -> 0.58145065 | H29: =VLOOKUP(A29,'brand list'!$G$1:$H$29,2,0) -> 大中华区 | J29: 昂跑 | K29: 59.55 | L29: 60.63 | M29: 62.82 | N29: 61 | P29: 昂跑 | Q29: 4.44 | R29: 10.45 | S29: 6.76 | T29: 7.2166667 | V29: 捷安特 | W29: 15.936852 | X29: 16.380126 | Y29: 18.017231 | Z29: 16.77807
A30: 美津浓 | B30: 1384560 | C30: 1599072 | D30: 1696848 | E30: 1560160 | F30: =C30/B30-1 -> 0.15493153 | G30: =D30/C30-1 -> 0.061145464 | H30: =VLOOKUP(A30,'brand list'!$G$1:$H$29,2,0) -> 亚太区 | J30: 彪马 | K30: 47 | L30: 47.6 | M30: 45 | N30: 46.533333 | P30: 哥伦比亚 | Q30: 3.2 | R30: 3.6 | S30: 3.9 | T30: 3.5666667 | V30: 牧高笛 | X30: 20.33 | Y30: 25.68 | Z30: 23.005
A31: 探路者 | B31: 1390710.9 | C31: 1591589.6 | D31: 1380713.1 | E31: 1454337.9 | F31: =C31/B31-1 -> 0.14444316 | G31: =D31/C31-1 -> -0.13249428 | H31: =VLOOKUP(A31,'brand list'!$G$1:$H$29,2,0) -> 中国公司 | J31: 哥伦比亚 | K31: 49.5 | L31: 50 | M31: 50.2 | N31: 49.9 | P31: 捷安特 | Q31: 4.63 | R31: 2.08 | S31: 1.44 | T31: 2.7166667 | V31: 斯凯奇 | W31: 42.1 | X31: 43.1 | Z31: 42.6
A32: 牧高笛 | C32: 760522 | D32: 787967 | E32: 778818.67 | G32: =D32/C32-1 -> 0.036087056 | H32: =VLOOKUP(A32,'brand list'!$G$1:$H$29,2,0) -> 中国内地 | J32: 捷安特 | K32: 22.06 | L32: 18.99 | M32: 19.81 | N32: 20.286667 | P32: 牧高笛 | Q32: 7.33 | R32: 6.42 | S32: -3.38 | T32: 3.4566667 | V32: 威富集团 | W32: 47.9 | X32: 49.4 | Y32: 48.5 | Z32: 48.6
A33: Grand Total | B33: 14113233 | C33: 15629752 | D33: 14823630 | E33: 14874981 | J33: 美津浓 | K33: 40.5 | L33: 41.8 | M33: 41.9 | N33: 41.4 | P33: 斯凯奇 | Q33: 6.8 | R33: 8.1 | T33: 7.45 | V33: 亚玛芬 | W33: 45.8 | X33: 46.9 | Y33: 47.3 | Z33: 46.666667
J34: 牧高笛 | K34: 28.3 | L34: 28.48 | M34: 28.61 | N34: 28.463333 | P34: 威富集团 | Q34: -9.8 | R34: -2 | S34: 2.7 | T34: -3.0333333 | V34: Grand Total | W34: 39.192107 | X34: 38.410014 | Y34: 38.453404 | Z34: 38.674168
J35: 斯凯奇 | K35: 51.9 | L35: 53.2 | N35: 52.55 | P35: 亚玛芬 | Q35: -4.7 | R35: 1.5 | S35: 6.7 | T35: 1.1666667
J36: 威富集团 | K36: 51.6 | L36: 53.5 | M36: 54.8 | N36: 53.3 | P36: adidas AG | Q36: -0.3 | R36: 3.5 | S36: 5.6 | T36: 2.9333333
J37: 亚玛芬 | K37: 52.45205 | L37: 55.404858 | M37: 57.63303 | N37: 55.163312 | P37: Decathlon SA | Q37: 5.97 | R37: 4.86 | S37: 5.42 | T37: 5.4166667
J38: adidas AG | K38: 47.5 | L38: 50.8 | M38: 51.6 | N38: 49.966667 | P38: Grand Total | Q38: 4.5294444 | R38: 6.8952814 | S38: 5.0039137 | T38: 5.5384149 | V38: 归一化指标名称 | W38: 经营费用
J39: Grand Total | K39: 47.422807 | L39: 48.526452 | M39: 48.609699 | N39: 48.175993 | V39: 区域 | W39: (Multiple Items)
V41: 平均值项:归一化指标数值 | W41: Column Labels
V42: Row Labels | W42: Grand Total
V43: Grand Total
...

Sheet brand list
A1: # | B1: 公司名称 | C1: 公司 / 集团名称 | D1: 企业国别 | E1: 对应核心品牌 | G1: 归一化指标名称 | H1: 营业收入
A2: 1 | B2: Lululemon athletica inc. | C2: Lululemon | D2: MCN | E2: Lululemon（露露乐蒙）
A3: 2 | B3: 斯凯奇 | C3: 斯凯奇 | D3: MCN | E3: Skechers（斯凯奇） | G3: Row Labels | H3: 区域
A4: 3 | B4: Nike | C4: Nike | D4: MCN | E4: Nike（耐克）、Converse（匡威）、Jordan（乔丹） | G4: 361度 | H4: 中国公司
A5: 4 | B5: Adidas AG | C5: Adidas | D5: MCN | E5: Adidas（阿迪达斯）、Reebok（锐步）、TaylorMade、Y-3 | G5: Adidas | H5: 大中华区
A6: 5 | B6: ASICS Corporation | C6: ASICS | D6: MCN | E6: ASICS（亚瑟士）、Onitsuka Tiger（鬼塚虎） | G6: ASICS | H6: 中国内地
A7: 6 | B7: Canada Goose Holdings Inc | C7: Canada Goose | D7: MCN | E7: Canada Goose（加拿大鹅） | G7: Canada Goose | H7: 大中华区
A8: 7 | B8: 彪马公司 | C8: 彪马 | D8: MCN | E8: PUMA（彪马） | G8: Inditex | H8: 亚太/其他地区
A9: 8 | B9: 亚玛芬 | C9: 亚玛芬 | D9: MCN | E9: Amer Sports（亚玛芬），旗下完整品牌：Arc'teryx（始祖鸟）、Salomon（萨洛蒙）、Wilson（威尔胜）、Atomic（阿托米克滑雪）、Peak Performance（壁克峰）、Suunto（颂拓户外腕表）、MAVIC、DEMARINI、Louisville Slugger、Rawlings、ARMADA、Glashütte Original | G9: Lululemon | H9: 中国内地
A10: 9 | B10: 美津浓公司 | C10: 美津浓 | D10: MCN | E10: Mizuno（美津浓） | G10: Nike | H10: 大中华区
A11: 10 | B11: 哥伦比亚运动服装公司 | C11: 哥伦比亚 | D11: MCN | E11: Columbia（哥伦比亚）、Mountain Hardwear、Sorel、Prana | G11: Topgolf Callaway | H11: 亚太区
A12: 11 | B12: 捷安特 | C12: 捷安特 | D12: 中国 | E12: Giant（捷安特）、Liv（女性系列）、Momentum | G12: Uniqlo | H12: 大中华区
A13: 12 | B13: Topgolf Callaway Brands Corp | C13: Topgolf Callaway | D13: MCN | E13: Callaway（卡拉威）、Topgolf、Odyssey、TravisMathew、OGIO、Jack Wolfskin（狼爪）、Toptracer、WGT | G13: 安德玛 | H13: 亚太区
A14: 13 | B14: 威富集团 | C14: 威富集团 | D14: MCN | E14: VF Corporation（威富集团），旗下完整品牌：The North Face（北面）、Vans（万斯）、Timberland（添柏岚）、Altra、icebreaker、JanSport、Kipling、Napapijri、Smartwool、Eastpak、Reef | G14: 安踏 | H14: 中国公司
... A27: 26 | B27: Inditex | C27: Inditex | D27: MCN | E27: ZARA、Pull&Bear、Massimo Dutti、Bershka、Stradivarius、Oysho、Uterque、ZARA HOME、Lefties | G27: 特步 | H27: 中国公司
G28: 威富集团 | H28: 亚太区
G29: 亚玛芬 | H29: 大中华区
G30: Grand Total

Sheet Parameters
A2: Modual A：规模与增长 - 了解市场地位与扩张速度
B3: 核心关注点 | C3: DKT对标 | D3: 国内财报常用术语 | E3: 国际（尤其美股）财报常用术语 | F3: 分析要点
A4: ⭐⭐ | B4: 1. 营业收入/销售额 | C4: TO | D4: 营业收入、主营业务收入、销售额 | E4: Revenue, Sales, Net Sales | F4: 绝对规模与趋势。这是最顶层的指标，反映市场占有率。需关注同比/环比增长率、季度/年度趋势。
A5: ⭐ | B5: 2. 同店销售增长 | D5: 同店销售额增长率、可比门店销售增长 | E5: Comparable Store Sales Growth (Comps/SSSG) | F5: 内生增长质量。剔除新开店影响，反映现有门店的经营健康状况和品牌吸引力，对零售业至关重要。
A7: Modual B：盈利能力 - 分析赚钱效率与商业模式优劣
B8: 核心关注点 | D8: 国内财报常用术语 | E8: 国际财报常用术语 | F8: 分析要点
A9: ⭐⭐ | B9: 3. 毛利率 | C9: Gross Margin | D9: 毛利率 = (营业收入 - 营业成本) / 营业收入 | E9: Gross Margin = (Revenue - Cost of Goods Sold) / Revenue | F9: 产品竞争力与成本控制。高毛利率通常意味着品牌溢价强或供应链成本控制好。是分析盈利能力的第一个关键节点。
A10: ⭐ | B10: 4. 营业利润/率 | D10: 营业利润、营业利润率 | E10: Operating Income, Operating Profit Margin | F10: 核心业务的经营效率。扣除了销售、管理、研发等运营费用，反映主营业务的真实盈利能力。
A11: ⭐⭐ | B11: 5. 净利润/率 | C11: EBIT | D11: 净利润、归属于母公司股东的净利润、净利率 | E11: Net Income, Net Profit Margin, EBIT | F11: 最终盈利成果。包含所有收入、成本、税费和一次性项目。净利率的变动趋势能揭示整体盈利能力的稳定性。
A13: Modual C：运营效率与财务健康度 - 评估经营稳健性与风险
B14: 核心关注点 | D14: 国内财报常用术语 | E14: 国际财报常用术语 | F14: 分析要点
A15: ⭐ | B15: 6. 运营费用率 | D15: 销售费用率、管理费用率、研发费用率 | E15: SG&A Rate (销售、一般及行政费用率), R&D Expense Rate | F15: 成本结构与管理水平。特别是销售费用率，对于零售和运动品牌而言，反映了市场推广和渠道成本的效率。
A16: ⭐ | B16: 7. 库存周转率/天数 | D16: 存货周转率、存货周转天数 | E16: Inventory Turnover, Days Sales of Inventory (DSI) | F16: 供应链与商品管理核心。对于迪卡侬这类体育用品零售商，库存积压是巨大风险。低周转率可能预示产品滞销或采购失误。
B17: 8. 经营活动现金流量净额 | D17: 经营活动产生的现金流量净额 | E17: Net Cash Provided by Operating Activities | F17: ‍“造血”能力。利润可能受会计处理影响，但现金流是实打实的。健康的公司应有稳定为正且与净利润匹配的经营现金流。
B18: 9. 关键资产负债指标 | D18: 资产负债率、流动比率、速动比率 | E18: Debt-to-Asset Ratio, Current Ratio, Quick Ratio | F18: 财务杠杆与短期偿债风险。高负债率在扩张期常见，但需警惕偿债风险。流动比率反映短期支付能力。
A20: Modual D：战略与长期价值 - 洞察未来潜力与投资方向
B21: 核心关注点 | D21: 国内财报常用术语 | E21: 国际财报常用术语 | F21: 分析要点
B22: 10. 资本支出 | D22: 购建固定资产等支付的现金 | E22: Capital Expenditures (CapEx) | F22: 未来扩张与再投资。高资本支出可能意味着正在积极开店、建厂或升级物流，是判断增长意图的重要信号。
A23: ⭐ | B23: 11. 坪效/单店收入 | D23: 坪效、每平方米销售额 | E23: Sales per Square Meter/Foot | F23: 门店运营效率。直接衡量门店空间利用效率和选址、运营水平，是零售业内部效率的核心对标指标。
B24: 12. 研发投入 | D24: 研发费用 | E24: Research & Development (R&D) Expense | F24: 创新与未来产品力。对于运动品牌，研发投入关乎新材料、新科技的应用，是长期竞争力的来源。
A26: 口径说明
A28: 1. 时间口径
A29: 按财年覆盖月份较多的年份进行归一化处理。例如，2025年数据包含财年结束于2026年5月31日（即2025年6月1日至2026年5月31日）的财务年度数据。
A30: 2. 区域口径
A31: 由于不同品牌披露的区域划分粒度不一，数据录入按以下优先级执行：中国大陆 > 大中华区 > 亚太区 > 全球。所列品牌的营业收入均已统一至不高于“亚太”层级的口径。在进行同市场数据对比时，需注意口径差异，建议优先关注增速指标。其他盈利及经营类数据（如毛利率、经营利润率、经营费用增速等）多为全球口径，分析时优先关注占比与增速。
A32: 3. 货币单位
A33: 对于跨国公司（MNC），若原始数据以母公司所在国货币列示，已统一换算为人民币。本次分析不考虑汇率波动带来的影响。

Sheet Coverage
A2: 一、品牌总览 (24家公司)
A3: 排名 | B3: 公司名称 | C3: 数据条数 | D3: 覆盖年份 | E3: 区域 | F3: 指标数量
A4: 1 | B4: 斯凯奇 | C4: 35 | D4: FY23-25 | E4: TOTAL, 中国内地 | F4: 10
A5: 2 | B5: 安德玛 | C5: 35 | D5: FY23-25 | E5: TOTAL, 亚太区 | F5: 10
A6: 3 | B6: 滔搏國際控股 | C6: 30 | D6: FY23-25 | E6: 中国公司 | F6: 10
A7: 4 | B7: 安踏体育 | C7: 30 | D7: FY23-25 | E7: TOTAL, 中国公司 | F7: 8
A8: 5 | B8: Lululemon | C8: 27 | D8: FY23-25 | E8: TOTAL | F8: 9
A9: 6 | B9: Adidas AG | C9: 24 | D9: FY23-25 | E9: TOTAL, 大中华区 | F9: 7
A10: 7 | B10: Nike | C10: 24 | D10: FY23-25 | E10: 大中华区 | F10: 8
A11: 8 | B11: 威富集团 | C11: 24 | D11: FY23-25 | E11: TOTAL | F11: 8
A12: 9 | B12: 哥伦比亚 | C12: 21 | D12: FY23-25 | E12: TOTAL, 亚太区 | F12: 6
A13: 10 | B13: On Holding AG | C13: 20 | D13: FY23-25 | E13: TOTAL, 亚太区 | F13: 6
A14: 11 | B14: 李宁公司 | C14: 18 | D14: FY23-25 | E14: 中国公司 | F14: 6
A15: 12 | B15: 361度 | C15: 18 | D15: FY23-25 | E15: 中国公司 | F15: 6
... A27: 24 | B27: Lululemon中国 | C27: 3 | D27: FY23-25 | E27: 中国内地 | F27: 1
A28: 二、核心指标覆盖矩阵
A29: 公司 | B29: 营业收入 | C29: 毛利润 | D29: 毛利率 | E29: 经营利润 | F29: 经营利润率 | G29: 净利润 | H29: 净利率 | I29: 运营费用率 | J29: 库存天数 | K29: 单店收入
A30: 斯凯奇 | B30: ✅ | C30: ✅ | D30: ✅TTL | E30: ✅ | F30: ✅ | G30: ✅ | H30: ✅ | I30: ✅ | J30: ✅ | K30: ✅
A31: 安德玛 | B31: ✅ | C31: ✅ | D31: ✅ | E31: ✅ | F31: ✅ | G31: ✅ | H31: ✅ | I31: ✅ | J31: ✅ | K31: ✅
A32: 滔搏 | B32: ✅ | C32: ✅ | D32: ✅ | E32: ✅ | F32: ✅ | G32: ✅ | H32: ✅ | I32: ✅ | J32: ✅ | K32: ✅
A33: 安踏 | B33: ✅ | C33: ✅ | D33: ✅ | E33: ✅ | F33: ❌ | G33: ❌ | H33: ✅ | I33: ✅ | J33: ✅ | K33: ✅
A34: Nike | B34: ✅ | C34: ✅ | D34: ✅ | E34: ✅ | F34: ✅ | G34: ❌ | H34: ✅ | I34: ✅ | J34: ✅ | K34: ❌
A35: Adidas | B35: ✅ | C35: ✅ | D35: ✅ | E35: ✅ | F35: ✅ | G35: ❌ | H35: ❌ | I35: ✅ | J35: ✅ | K35: ❌
A36: Lululemon | B36: ✅ | C36: ❌ | D36: ✅ | E36: ✅ | F36: ✅ | G36: ✅ | H36: ✅ | I36: ✅ | J36: ✅ | K36: ✅
A37: VF Corp | B37: ✅ | C37: ❌ | D37: ✅ | E37: ✅ | F37: ✅ | G37: ✅ | H37: ✅ | I37: ✅ | J37: ✅ | K37: ❌
A38: Columbia | B38: ✅ | C38: ❌ | D38: ✅ | E38: ✅ | F38: ✅ | G38: ✅ | H38: ✅ | I38: ❌ | J38: ❌ | K38: ❌
A39: 李宁 | B39: ✅ | C39: ✅ | D39: ✅ | E39: ❌ | F39: ❌ | G39: ❌ | H39: ✅ | I39: ✅ | J39: ❌ | K39: ✅
A40: 361度 | B40: ✅ | C40: ✅ | D40: ✅ | E40: ❌ | F40: ❌ | G40: ❌ | H40: ✅ | I40: ✅ | J40: ❌ | K40: ✅
... A52: Topgolf | B52: ✅ | C52: ❌ | D52: ❌ | E52: ❌ | F52: ❌ | G52: ❌ | H52: ❌ | I52: ❌ | J52: ❌ | K52: ❌
A53: 奔赴自然 | B53: ✅
A55: 三、区域覆盖分类
A56: 🇨🇳 中国公司 (11家)
A57: 公司 | B57: 区域 | C57: 年份 | D57: 指标数
A58: 滔搏國際 | B58: 中国公司 | C58: FY23-25 | D58: 10
A59: 安踏体育 | B59: TOTAL, 中国公司 | C59: FY23-25 | D59: 8
A60: 李宁公司 | B60: 中国公司 | C60: FY23-25 | D60: 6
A61: 361度 | B61: 中国公司 | C61: FY23-25 | D61: 6
A62: 特步国际 | B62: 中国公司 | C62: FY23-25 | D62: 6
A63: 探路者 | B63: 中国公司 | C63: FY23-25 | D63: 5
A64: 牧高笛 | B64: 中国公司 | C64: FY23-25 | D64: 5
...

Sheet 1.1 Revenue
A2: 1. 行业趋势：营收、毛利率、净利率、营业利润率、营业费用率 变化趋势
A4: 指标 | B4: FY2023 | C4: FY2024 | D4: FY2025 | E4: 趋势
A5: 营收增速 | B5: - | C5: =B45 -> 0.11204788 | D5: =C45 -> -0.057316817 | E5: 25年xx%品牌营收下滑
A6: 毛利率均值 | B6: 0.49762824 | C6: 0.49432742 | D6: 0.49216957 | E6: ↓ 小幅下滑
A7: 净利率均值 | B7: 0.083706725 | C7: 0.098667557 | D7: 0.080184147 | E7: ↑后↓
A8: 运营费用率均值 | B8: 0.33505109 | C8: 0.33360563 | D8: 0.34101602 | E8: 2025年小涨↓
A15: 2. 品牌营收表现
A18: 品牌 | B18: FY23-24变化率(%) | C18: FY24-25变化率(%) | D18: 2025营收 | E18: 覆盖区域
A19: 安踏 | B19: 0.13583296 | C19: 0.13262079 | D19: 80219000 | E19: =VLOOKUP(A19,'brand list'!$G$1:$H$29,2,0) -> 中国公司
A20: Nike | B20: 0.040976821 | C20: -0.12710404 | D20: 47419200 | E20: =VLOOKUP(A20,'brand list'!$G$1:$H$29,2,0) -> 大中华区
A21: Inditex | B21: -0.0091743119 | C21: -0.025673401 | D21: 36114000 | E21: =VLOOKUP(A21,'brand list'!$G$1:$H$29,2,0) -> 亚太/其他地区
A22: 李宁 | B22: 0.039060802 | C22: 0.032152322 | D22: 29598000 | E22: =VLOOKUP(A22,'brand list'!$G$1:$H$29,2,0) -> 中国公司
A23: 滔搏 | B23: 0.068702628 | C23: -0.066370122 | D23: 27012900 | E23: =VLOOKUP(A23,'brand list'!$G$1:$H$29,2,0) -> 中国公司
A24: Adidas | B24: 0.084326019 | C24: 0.047412547 | D24: 28259400 | E24: =VLOOKUP(A24,'brand list'!$G$1:$H$29,2,0) -> 大中华区
A25: 特步 | B25: 0.065471753 | C25: 0.042269393 | D25: 14151100 | E25: =VLOOKUP(A25,'brand list'!$G$1:$H$29,2,0) -> 中国公司
A26: 威富集团 | B26: 0.013854129 | C26: -0.013714719 | D26: 10102990 | E26: =VLOOKUP(A26,'brand list'!$G$1:$H$29,2,0) -> 亚太区
A27: 361度 | B27: 0.19591626 | C27: 0.10644939 | D27: 11145829 | E27: =VLOOKUP(A27,'brand list'!$G$1:$H$29,2,0) -> 中国公司
A28: Lululemon | B28: 0.41252698 | C28: 0.28902616 | D28: 12634553 | E28: =VLOOKUP(A28,'brand list'!$G$1:$H$29,2,0) -> 中国内地
A29: 亚玛芬 | B29: 0.5365767 | C29: 0.43432709 | D29: 13405680 | E29: =VLOOKUP(A29,'brand list'!$G$1:$H$29,2,0) -> 大中华区
A30: 斯凯奇 | B30: -0.008500525 | E30: =VLOOKUP(A30,'brand list'!$G$1:$H$29,2,0) -> 中国内地
A31: 捷安特 | B31: 0.074583514 | C31: -0.37084727 | D31: 4478649.5 | E31: =VLOOKUP(A31,'brand list'!$G$1:$H$29,2,0) -> 亚太区
A32: 安德玛 | B32: 0.057771483 | C32: -0.13468435 | D32: 5439146.4 | E32: =VLOOKUP(A32,'brand list'!$G$1:$H$29,2,0) -> 亚太区
A33: 彪马 | B33: 0.037444177 | C33: -0.19139073 | D33: 3809520 | E33: =VLOOKUP(A33,'brand list'!$G$1:$H$29,2,0) -> 大中华区
A34: 哥伦比亚 | B34: 0.078280769 | C34: 0.089963368 | D34: 4400272.8 | E34: =VLOOKUP(A34,'brand list'!$G$1:$H$29,2,0) -> 亚太区
A35: 比音勒芬 | B35: 0.13244147 | C35: 0.077275682 | D35: 4313911 | E35: =VLOOKUP(A35,'brand list'!$G$1:$H$29,2,0) -> 中国公司
A36: ASICS | B36: 0.30494782 | C36: 0.19421627 | D36: 3932816 | E36: =VLOOKUP(A36,'brand list'!$G$1:$H$29,2,0) -> 中国内地
A37: Topgolf Callaway | B37: -0.083286332 | C37: -0.25533224 | D37: 2614320 | E37: =VLOOKUP(A37,'brand list'!$G$1:$H$29,2,0) -> 亚太区
A38: Canada Goose | B38: 0.010184747 | C38: 0.16834701 | D38: 2740650 | E38: =VLOOKUP(A38,'brand list'!$G$1:$H$29,2,0) -> 大中华区
A39: 昂跑 | B39: 0.84408221 | C39: 0.96425826 | D39: 4139910 | E39: =VLOOKUP(A39,'brand list'!$G$1:$H$29,2,0) -> 亚太区
A40: 奔赴自然(伯希和） | B40: 0.94482986 | C40: 0.58145065 | D40: 2793000 | E40: =VLOOKUP(A40,'brand list'!$G$1:$H$29,2,0) -> 大中华区
A41: 美津浓 | B41: 0.15493153 | C41: 0.061145464 | D41: 1696848 | E41: =VLOOKUP(A41,'brand list'!$G$1:$H$29,2,0) -> 亚太区
A42: 探路者 | B42: 0.14444316 | C42: -0.13249428 | D42: 1380713.1 | E42: =VLOOKUP(A42,'brand list'!$G$1:$H$29,2,0) -> 中国公司
A43: 牧高笛 | C43: 0.036087056 | D43: 787967 | E43: =VLOOKUP(A43,'brand list'!$G$1:$H$29,2,0) -> 中国内地
A44: Uniqlo | B44: 0.09158336 | C44: -0.039586411 | D44: 31158400 | E44: =VLOOKUP(A44,'brand list'!$G$1:$H$29,2,0) -> 大中华区
A45: 总计 | B45: 0.11204788 | C45: -0.057316817 | D45: 13979069
A47: 3. 毛利率
A49: 品牌 | B49: 2023 | C49: 2024 | D49: 2025 | E49: 覆盖区域
A50: 比音勒芬 | B50: 77.5 | C50: 76.29 | D50: 75.35 | E50: =VLOOKUP(A50,'brand list'!$G$1:$H$29,2,0) -> 中国公司
A51: 昂跑 | B51: 59.55 | C51: 60.63 | D51: 62.82 | E51: 全球
A52: 安踏 | B52: 62.6 | C52: 62.2 | D52: 62 | E52: =VLOOKUP(A52,'brand list'!$G$1:$H$29,2,0) -> 中国公司
...

Sheet 361度财报深度分析
A1: 361度 2023-2025年财报深度分析
A3: 一、整体经营规模 & 增长维度
A5: 营收规模与增速
A7: 指标 | B7: 2023年 | C7: 2024年 | D7: 2025年 | E7: 24→25趋势
A8: 总营收 | B8: 84.2亿元 | C8: 100.7亿元 | D8: 111.5亿元 | E8: 0.106
A9: 同比增速 | B9: - | C9: 0.196 | D9: 0.106 | E9: 增速放缓
A10: 净利润 | B10: 9.6亿元 | C10: 11.5亿元 | D10: 13.1亿元 | E10: 0.14
A11: 净利率 | B11: 0.114 | C11: 0.114 | D11: 0.117 | E11: 稳中有升
A13: 判断：生意底盘从"高速扩张"转向"稳质增长"。2024年受益于疫后复苏+儿童业务发力，营收增长19.6%为三年高点；2025年增速回落至10.6%但净利增速14%高于营收，体现提质增效。
A15: 收入结构拆解
A17: 品类 | B17: 2023年 | C17: 2024年 | D17: 2025年 | E17: 三年变化
A18: 成人鞋类 | B18: - | C18: 42.9亿(42.6%) | D18: 46.3亿(41.5%) | E18: 占比↓
A19: 成人服装 | B19: - | C19: 30.9亿(30.7%) | D19: 34.2亿(30.7%) | E19: 持平
A20: 儿童鞋类 | B20: - | C20: 11.0亿(10.9%) | D20: 14.1亿(12.7%) | E20: 占比↑↑
A21: 儿童服装 | B21: - | C21: 12.1亿(12.0%) | D21: 11.2亿(10.0%) | E21: 占比↓
A22: 其他 | B22: - | C22: 3.8亿(3.8%) | D22: 5.6亿(5.1%) | E22: 占比↑
A24: 洞察：儿童鞋类成为最大亮点，3年复合增长约28.5%；儿童服装2025年出现下滑（-7.5%），需关注品类竞争力。
A26: 渠道结构变化
A28: 渠道 | B28: 2023年 | C28: 2024年 | D28: 2025年 | E28: 趋势
A29: 电商 | B29: 23.3亿(27.6%) | C29: 26.1亿(25.9%) | D29: 32.9亿(29.5%) | E29: 占比↑↑
A30: 线下 | B30: 61.0亿(72.4%) | C30: 74.6亿(74.1%) | D30: 78.6亿(70.5%) | E30: 占比↓
A32: 洞察：电商占比从27.6%→29.5%，2025年单年电商增长25.9%远超整体增速，成为核心增长引擎。线下占比下降但绝对额仍增长，显示全渠道布局健康。
A34: 门店规模与效率
A36: 品牌 | B36: 2023年末 | C36: 2024年末 | D36: 2025年末 | E36: 三年变化
A37: 主品牌 | B37: 5,734家 | C37: 5,750家 | D37: 5,394家 | E37: 净减360家
A38: 儿童 | B38: 2,545家 | C38: 2,548家 | D38: 2,364家 | E38: 净减181家
A39: 国际 | B39: - | C39: 1,365家 | D39: 1,253家 | E39: 净减112家
A41: 洞察：主品牌门店2024年基本持平，2025年净减356家；儿童净减184家。 关店主要发生在一二线城市（单店面积从149㎡→165㎡），重心转向三线以下城市（占比76.1%）和提升单店质量。这是从"粗放开店"转向"精细化提店效"的关键信号。
A43: 区域分布（2025年）
A45: 区域 | B45: 主品牌占比 | C45: 儿童占比
A46: 北部 | B46: 0.463 | C46: 0.458
A47: 西部 | B47: 0.213 | C47: 0.205
A48: 东部 | B48: 0.204 | C48: 0.2
A49: 南部 | B49: 0.12 | C49: 0.137
A52: 二、盈利 & 毛利健康度维度
A54: 毛利率
A56: 品类 | B56: 2023年 | C56: 2024年 | D56: 2025年 | E56: 变化
A57: 综合毛利率 | B57: 0.411 | C57: 0.415 | D57: 0.415 | E57: +0.4pp
A58: 成人鞋类 | B58: - | C58: 0.429 | D58: 0.43 | E58: +0.1pp
A59: 成人服装 | B59: - | C59: 0.413 | D59: 0.424 | E59: +1.1pp ✅
...

Sheet 安踏财报深度分析
A1: 安踏体育 2023-2025年财报深度分析
A2: 一、整体经营规模 & 增长维度
A3: 营收规模与增速
A4: 指标 | B4: 2023年 | C4: 2024年 | D4: 2025年 | E4: 24→25趋势
A5: 总收入 | B5: 623.6亿元 | C5: 708.3亿元 | D5: 802.2亿元 | E5: 0.133
A6: 同比增速 | B6: - | C6: 0.136 | D6: 0.133 | E6: 持平稳健
A7: 净利润（含Amer利得） | B7: 102.4亿元 | C7: 156.0亿元 | D7: 135.9亿元 | E7: -0.129
A8: 经调整净利润 | B8: 109.5亿元 | C8: 117.3亿元 | D8: 123.9亿元 | E8: 0.056
A9: 净利率（经调整） | B9: 0.176 | C9: 0.166 | D9: 0.154 | E9: 结构性下降
A11: 判断：安踏已进入"600亿+俱乐部"，收入增速稳定在13%左右。经调整净利润2025年增长5.6%达124亿，但净利率从17.6%（2023）→15.4%（2025）呈下降趋势，主要因低利润率的其他品牌（Descente/Kolon/MAIA等）占比提升所致。
A12: 品牌收入结构拆解
A13: 品牌 | B13: 2023年 | C13: 2024年 | D13: 2025年 | E13: 三年变化
A14: 安踏主品牌 | B14: 303.1亿(48.6%) | C14: 335.2亿(47.3%) | D14: 347.5亿(43.3%) | E14: 占比↓
A15: FILA | B15: 251.0亿(40.3%) | C15: 266.3亿(37.6%) | D15: 284.7亿(35.5%) | E15: 占比↓
A16: 其他品牌 | B16: 69.5亿(11.1%) | C16: 106.8亿(15.1%) | D16: 170.0亿(21.2%) | E16: 占比↑↑↑
A18: 洞察：安踏主品牌和FILA占比逐年下降，"所有其他品牌"从11.1%→21.2%翻倍，2025年已贡献近170亿收入。Descente/Kolon Sport/MAIA ACTIVE等高端品牌高速增长，驱动收入结构高端化。
A19: 品类结构
A20: 品类 | B20: 2025年 | C20: 占比 | D20: 同比
A21: 服装 | B21: 458.1亿 | C21: 0.571 | D21: 0.163
A22: 鞋类 | B22: 315.0亿 | C22: 0.393 | D22: 0.079
A23: 配饰 | B23: 29.1亿 | C23: 0.036 | D23: 0.298
A24: 渠道结构
A25: 渠道 | B25: 2025年（安踏分部） | C25: 占比
A26: 电商 | B26: 128.6亿 | C26: 0.37
A27: DTC-直营 | B27: 123.1亿 | C27: 0.354
A28: DTC-加盟 | B28: 63.9亿 | C28: 0.184
A29: 传统批发 | B29: 31.9亿 | C29: 0.092
A31: 洞察：安踏DTC转型成功，直营+加盟DTC合计占安踏收入53.8%，电商占37%。FILA品牌全部门店为直营。
A32: 门店规模
A33: 品牌 | B33: 2023年末 | C33: 2024年末 | D33: 2025年末 | E33: 趋势
A34: 安踏主品牌 | B34: - | C34: 7135 | D34: 7203 | E34: 稳增
A35: FILA | B35: - | C35: 1264 | D35: 2,652（含kids/fusion） | E35: 调整整合
A36: DESCENTE | B36: - | C36: 226 | D36: 256 | E36: 扩张
A37: KOLON SPORT | B37: - | C37: 191 | D37: 209 | E37: 扩张
A38: MAIA ACTIVE | B38: - | C38: 1264 | D38: 1273 | E38: 稳增
A39: 安踏儿童 | B39: - | C39: 2784 | D39: 578（单独列示） | E39: 独立运营
A41: 洞察：安踏主品牌门店稳定在7100+家，Descente/Kolon持续扩张。FILA门店2025年含Kids/Fusion合并披露（实际净关店，从约2000家整合至1900家水平）。
A42: 二、盈利 & 毛利健康度维度
A43: 毛利率
A44: 指标 | B44: 2023年 | C44: 2024年 | D44: 2025年 | E44: 趋势
...

Sheet Quote
D2: Operating expenses
B3: 斯凯奇 | C3: 2024 | D3: Operating expenses Operating expenses increased $495.6 million, or 14.7%, to $3.9 billion, and as a percentage of sales increased 100 basis points to 43.1%. Selling expenses increased $123.7 million, or 18.3%, to $800.6 million, primarily due to higher demand creation expenditures in global marketing and digital advertising. General and administrative expenses increased $371.8 million, or 13.8%, to $3.1 billion. The increased expenses were driven by increases in labor costs of $179.8 million, facility related costs of $79.8 million, including rent and depreciation, and legal costs of $22.3 million
